Workbook

Sheet À traiter
A1: History Pins — Master des histoires à traiter (Métronome + Hexagone)
A2: 95 histoires au total (49 Métronome / Paris + 46 Hexagone / France). Sans doublon avec stories.ts ni entre les deux livres. Une ligne = une histoire ; coordonnées = lieu réel.
A4: N° | B4: Livre | C4: Chapitre (siècle · lieu/route) | D4: N° ds chap. | E4: Histoire / anecdote | F4: Personnages clés | G4: Lieu | H4: Lat | I4: Lng | J4: Période | K4: Commande /new-story | L4: Notes
A5: 1 | B5: Métronome | C5: 01 · Ier · Cité | D5: 1 | E5: La Lutèce gallo-romaine s'installe sur l'île de la Cité | F5: — | G5: Île de la Cité | H5: 48.855 | I5: 2.347 | J5: Ier s. | K5: /new-story La Lutèce gallo-romaine s'installe sur l'île de la Cité
A6: 2 | B6: Métronome | C6: 01 · Ier · Cité | D6: 2 | E6: Le pilier des nautes, plus vieux monument de Paris | F6: Nautes de Lutèce | G6: Sous Notre-Dame | H6: 48.853 | I6: 2.3499 | J6: Ier s. | K6: /new-story Le pilier des nautes, plus vieux monument de Paris
A7: 3 | B7: Métronome | C7: 01 · Ier · Cité | D7: 3 | E7: Les arènes de Lutèce | F7: — | G7: Arènes de Lutèce | H7: 48.8454 | I7: 2.353 | J7: Ier-IIe s. | K7: /new-story Les arènes de Lutèce
A8: 4 | B8: Métronome | C8: 02 · IIe · Place d'Italie | D8: 1 | E8: Le cardo maximus, grand axe romain (rue Saint-Jacques) | F8: — | G8: Rue Saint-Jacques | H8: 48.8462 | I8: 2.344 | J8: IIe s. | K8: /new-story Le cardo maximus, grand axe romain (rue Saint-Jacques)
A9: 5 | B9: Métronome | C9: 02 · IIe · Place d'Italie | D9: 2 | E9: « Tous les chemins mènent à Rome » : voies et bornes milliaires | F9: — | G9: Place d'Italie | H9: 48.8312 | I9: 2.3558 | J9: IIe s. | K9: /new-story « Tous les chemins mènent à Rome » : voies et bornes milliaires
A10: 6 | B10: Métronome | C10: 02 · IIe · Place d'Italie | D10: 3 | E10: Lutèce délaissée et pillée par les invasions germaniques | F10: — | G10: Rive gauche | H10: 48.844 | I10: 2.345 | J10: IIe-IIIe s. | K10: /new-story Lutèce délaissée et pillée par les invasions germaniques
A11: 7 | B11: Métronome | C11: 03 · IIIe · Notre-Dame-des-Champs | D11: 1 | E11: Le martyre de saint Denis, décapité à Montmartre | F11: Saint Denis | G11: Butte Montmartre | H11: 48.8867 | I11: 2.3431 | J11: IIIe s. | K11: /new-story Le martyre de saint Denis, décapité à Montmartre
A12: 8 | B12: Métronome | C12: 03 · IIIe · Notre-Dame-des-Champs | D12: 2 | E12: Saint Denis céphalophore portant sa tête jusqu'à Saint-Denis | F12: Saint Denis | G12: Vers Saint-Denis | H12: 48.91 | I12: 2.35 | J12: IIIe s. | K12: /new-story Saint Denis céphalophore portant sa tête jusqu'à Saint-Denis | L12: Légende
A13: 9 | B13: Métronome | C13: 03 · IIIe · Notre-Dame-des-Champs | D13: 3 | E13: Les premières communautés chrétiennes de Lutèce | F13: — | G13: Notre-Dame-des-Champs | H13: 48.8424 | I13: 2.33 | J13: IIIe s. | K13: /new-story Les premières communautés chrétiennes de Lutèce
A14: 10 | B14: Métronome | C14: 04 · IVe · Saint-Martin | D14: 1 | E14: Julien proclamé empereur à Lutèce (360) | F14: Julien l'Apostat | G14: Palais des Thermes (Cluny) | H14: 48.8503 | I14: 2.3439 | J14: 360 | K14: /new-story Julien proclamé empereur à Lutèce (360)
A15: 11 | B15: Métronome | C15: 04 · IVe · Saint-Martin | D15: 2 | E15: Julien repousse les Alamans (bataille de Strasbourg, 357) | F15: Julien | G15: (évoqué) Lutèce | H15: 48.8503 | I15: 2.3439 | J15: 357 | K15: /new-story Julien repousse les Alamans (bataille de Strasbourg, 357)
A16: 12 | B16: Métronome | C16: 04 · IVe · Saint-Martin | D16: 3 | E16: Saint Martin partage son manteau | F16: Saint Martin | G16: Rue Saint-Martin | H16: 48.8636 | I16: 2.3527 | J16: IVe s. | K16: /new-story Saint Martin partage son manteau
A17: 13 | B17: Métronome | C17: 04 · IVe · Saint-Martin | D17: 4 | E17: Lutèce prend le nom de Paris (civitas Parisiorum) | F17: — | G17: Île de la Cité | H17: 48.855 | I17: 2.347 | J17: fin IVe s. | K17: /new-story Lutèce prend le nom de Paris (civitas Parisiorum)
A18: 14 | B18: Métronome | C18: 05 · Ve · Saint-Michel–N.-D. | D18: 1 | E18: Geneviève ravitaille Paris assiégée par les Francs | F18: Sainte Geneviève | G18: Île de la Cité | H18: 48.8554 | I18: 2.345 | J18: Ve s. | K18: /new-story Geneviève ravitaille Paris assiégée par les Francs
A19: 15 | B19: Métronome | C19: 05 · Ve · Saint-Michel–N.-D. | D19: 2 | E19: Childéric et la montée des Mérovingiens | F19: Childéric Ier | G19: — | H19: 48.8554 | I19: 2.345 | J19: Ve s. | K19: /new-story Childéric et la montée des Mérovingiens
A20: 16 | B20: Métronome | C20: 06 · VIe · Saint-Germain-des-Prés | D20: 1 | E20: Mort de sainte Geneviève (502), tombeau sur le mont | F20: Sainte Geneviève, Clovis | G20: Abbaye Sainte-Geneviève | H20: 48.8462 | I20: 2.3464 | J20: 502 | K20: /new-story Mort de sainte Geneviève (502), tombeau sur le mont
A21: 17 | B21: Métronome | C21: 06 · VIe · Saint-Germain-des-Prés | D21: 2 | E21: Childebert fonde l'abbaye Saint-Germain-des-Prés | F21: Childebert Ier | G21: Saint-Germain-des-Prés | H21: 48.8539 | I21: 2.334 | J21: VIe s. | K21: /new-story Childebert fonde l'abbaye Saint-Germain-des-Prés
A22: 18 | B22: Métronome | C22: 06 · VIe · Saint-Germain-des-Prés | D22: 3 | E22: Les rois mérovingiens et les partages du royaume | F22: Mérovingiens | G22: — | H22: 48.8539 | I22: 2.334 | J22: VIe s. | K22: /new-story Les rois mérovingiens et les partages du royaume
A23: 19 | B23: Métronome | C23: 07 · VIIe · Basilique Saint-Denis | D23: 1 | E23: Dagobert et l'essor de l'abbaye de Saint-Denis | F23: Dagobert Ier | G23: Basilique Saint-Denis | H23: 48.9355 | I23: 2.3593 | J23: VIIe s. | K23: /new-story Dagobert et l'essor de l'abbaye de Saint-Denis
A24: 20 | B24: Métronome | C24: 07 · VIIe · Basilique Saint-Denis | D24: 2 | E24: Saint Éloi, orfèvre et conseiller du roi | F24: Saint Éloi | G24: Basilique Saint-Denis | H24: 48.9355 | I24: 2.3593 | J24: VIIe s. | K24: /new-story Saint Éloi, orfèvre et conseiller du roi
... A47: 43 | B47: Métronome | C47: 16 · XVIIe · Le Grand Siècle / Invalides | D47: 2 | E47: Louis XIV, le Roi-Soleil et Paris | F47: Louis XIV | G47: Paris | H47: 48.8554 | I47: 2.345 | J47: XVIIe s. | K47: /new-story Louis XIV, le Roi-Soleil et Paris
A48: 44 | B48: Métronome | C48: 17 · XVIIIe-XIXe · De la Bastille à la IIIe Rép. | D48: 1 | E48: La Commune de Paris (1871) | F48: Communards | G48: Montmartre | H48: 48.8867 | I48: 2.3431 | J48: 1871 | K48: /new-story La Commune de Paris (1871) | L48: Traitée brièvement dans le livre
A49: 45 | B49: Métronome | C49: 18 · XXe · Les allées du pouvoir | D49: 1 | E49: Le métro et les édicules Guimard (kiosque des Noctambules) | F49: Hector Guimard | G49: Place Colette / Palais-Royal | H49: 48.8636 | I49: 2.337 | J49: 1900-2000 | K49: /new-story Le métro et les édicules Guimard (kiosque des Noctambules)
A50: 46 | B50: Métronome | C50: 18 · XXe · Les allées du pouvoir | D50: 2 | E50: L'Élysée et les lieux du pouvoir républicain | F50: — | G50: Palais de l'Élysée | H50: 48.8704 | I50: 2.3166 | J50: XXe s. | K50: /new-story L'Élysée et les lieux du pouvoir républicain
A51: 47 | B51: Métronome | C51: 18 · XXe · Les allées du pouvoir | D51: 3 | E51: Guerres mondiales et Libération de Paris (1944) | F51: De Gaulle, Leclerc | G51: Hôtel de Ville | H51: 48.8565 | I51: 2.3512 | J51: 1944 | K51: /new-story Guerres mondiales et Libération de Paris (1944)
A52: 48 | B52: Métronome | C52: 19 · XXIe · La Défense | D52: 1 | E52: La Grande Arche de la Défense | F52: — | G52: Grande Arche | H52: 48.8924 | I52: 2.2389 | J52: 1989 | K52: /new-story La Grande Arche de la Défense
A53: 49 | B53: Métronome | C53: 19 · XXIe · La Défense | D53: 2 | E53: Le Grand Paris et la ville de demain | F53: — | G53: La Défense | H53: 48.8917 | I53: 2.236 | J53: XXIe s. | K53: /new-story Le Grand Paris et la ville de demain
A54: 50 | B54: Hexagone | C54: 01 · VIe av. J.-C. · Les routes du commerce | D54: 1 | E54: La fondation de Marseille (Massalia) par les Phocéens | F54: Gyptis, Protis | G54: Marseille (Vieux-Port) | H54: 43.2965 | I54: 5.3698 | J54: v. 600 av. J.-C. | K54: /new-story La fondation de Marseille (Massalia) par les Phocéens
A55: 51 | B55: Hexagone | C55: 01 · VIe av. J.-C. · Les routes du commerce | D55: 2 | E55: La route de l'étain de Cornouailles par les fleuves de Gaule | F55: — | G55: Vallée de la Seine (Rouen) | H55: 49.4431 | I55: 1.0993 | J55: VIe-Ve av. J.-C. | K55: /new-story La route de l'étain de Cornouailles par les fleuves de Gaule | L55: Axe fluvial
A56: 52 | B56: Hexagone | C56: 01 · VIe av. J.-C. · Les routes du commerce | D56: 3 | E56: Le trésor de Vix : la Dame et le cratère celte | F56: Dame de Vix | G56: Vix (Châtillon-sur-Seine) | H56: 47.8989 | I56: 4.5392 | J56: v. 500 av. J.-C. | K56: /new-story Le trésor de Vix : la Dame et le cratère celte
A57: 53 | B57: Hexagone | C57: 02 · Ve-IVe av. J.-C. · Les Celtes | D57: 1 | E57: Bibracte, capitale des Éduens (Mont Beuvray) | F57: Éduens | G57: Mont Beuvray | H57: 46.9239 | I57: 4.0392 | J57: Ve-IIe av. J.-C. | K57: /new-story Bibracte, capitale des Éduens (Mont Beuvray)
A58: 54 | B58: Hexagone | C58: 02 · Ve-IVe av. J.-C. · Les Celtes | D58: 2 | E58: Les routes de l'ambre, du sel et du fer | F58: — | G58: Salins-les-Bains | H58: 46.9417 | I58: 5.8783 | J58: Antiquité celte | K58: /new-story Les routes de l'ambre, du sel et du fer
A59: 55 | B59: Hexagone | C59: 03 · Ier av. J.-C. · La conquête romaine | D59: 1 | E59: Gergovie : la victoire de Vercingétorix sur César | F59: Vercingétorix, César | G59: Plateau de Gergovie | H59: 45.7186 | I59: 3.1239 | J59: 52 av. J.-C. | K59: /new-story Gergovie : la victoire de Vercingétorix sur César
A60: 56 | B60: Hexagone | C60: 03 · Ier av. J.-C. · La conquête romaine | D60: 2 | E60: Alésia : la reddition de Vercingétorix | F60: Vercingétorix, César | G60: Alise-Sainte-Reine | H60: 47.5375 | I60: 4.5006 | J60: 52 av. J.-C. | K60: /new-story Alésia : la reddition de Vercingétorix
A61: 57 | B61: Hexagone | C61: 04 · Ier-IIe s. · La Gaule romaine | D61: 1 | E61: Lugdunum (Lyon), capitale des Gaules | F61: — | G61: Fourvière, Lyon | H61: 45.7622 | I61: 4.8225 | J61: Ier s. | K61: /new-story Lugdunum (Lyon), capitale des Gaules
A62: 58 | B62: Hexagone | C62: 04 · Ier-IIe s. · La Gaule romaine | D62: 2 | E62: Le pont du Gard et l'aqueduc de Nîmes | F62: — | G62: Pont du Gard | H62: 43.9475 | I62: 4.535 | J62: Ier s. | K62: /new-story Le pont du Gard et l'aqueduc de Nîmes
A63: 59 | B63: Hexagone | C63: 04 · Ier-IIe s. · La Gaule romaine | D63: 3 | E63: Nîmes (Nemausus) et ses arènes | F63: — | G63: Arènes de Nîmes | H63: 43.8345 | I63: 4.3601 | J63: Ier-IIe s. | K63: /new-story Nîmes (Nemausus) et ses arènes
...

Sheet Décompte
A1: Décompte
A3: Par livre
A4: Livre | B4: Nombre
A5: Métronome | B5: =COUNTIF('À traiter'!$B$5:$B$99,$A5) -> 49
A6: Hexagone | B6: =COUNTIF('À traiter'!$B$5:$B$99,$A6) -> 46
A7: TOTAL | B7: =SUM(B5:B6) -> 95
A9: Par chapitre
A10: Chapitre | B10: Nombre
A11: 01 · Ier · Cité | B11: =COUNTIF('À traiter'!$C$5:$C$99,$A11) -> 3
A12: 02 · IIe · Place d'Italie | B12: =COUNTIF('À traiter'!$C$5:$C$99,$A12) -> 3
A13: 03 · IIIe · Notre-Dame-des-Champs | B13: =COUNTIF('À traiter'!$C$5:$C$99,$A13) -> 3
A14: 04 · IVe · Saint-Martin | B14: =COUNTIF('À traiter'!$C$5:$C$99,$A14) -> 4
A15: 05 · Ve · Saint-Michel–N.-D. | B15: =COUNTIF('À traiter'!$C$5:$C$99,$A15) -> 2
A16: 06 · VIe · Saint-Germain-des-Prés | B16: =COUNTIF('À traiter'!$C$5:$C$99,$A16) -> 3
A17: 07 · VIIe · Basilique Saint-Denis | B17: =COUNTIF('À traiter'!$C$5:$C$99,$A17) -> 3
A18: 08 · IXe · L'heure des comtes | B18: =COUNTIF('À traiter'!$C$5:$C$99,$A18) -> 3
A19: 09 · Xe · L'envol des Capétiens | B19: =COUNTIF('À traiter'!$C$5:$C$99,$A19) -> 2
A20: 10 · XIe · L'an mille | B20: =COUNTIF('À traiter'!$C$5:$C$99,$A20) -> 3
A21: 11 · XIIe-XIIIe · Philippe Auguste | B21: =COUNTIF('À traiter'!$C$5:$C$99,$A21) -> 1
A22: 12 · XIIIe · L'essor de l'Université | B22: =COUNTIF('À traiter'!$C$5:$C$99,$A22) -> 2
... A45: 16 · XXe-XXIe s. · Routes modernes | B45: =COUNTIF('À traiter'!$C$5:$C$99,$A45) -> 1
A46: TOTAL | B46: =SUM(B11:B45) -> 95
